Workbook

Sheet Resumen
A1: Inventario de contenido: Ferzamac (rediseño web)
A2: Los totales se calculan solos a partir de la hoja Inventario: si cambias una decisión o una calidad, se actualizan.
A4: Decisión | B4: Total | C4: Del catálogo PDF
A5: Usar | B5: =COUNTIF(Inventario!$H$2:$H$93,A5) -> 28 | C5: =COUNTIFS(Inventario!$H$2:$H$93,A5,Inventario!$B$2:$B$93,"Catálogo PDF") -> 23 | D5: Listas para publicar tal cual.
A6: Usar tras mejorar | B6: =COUNTIF(Inventario!$H$2:$H$93,A6) -> 44 | C6: =COUNTIFS(Inventario!$H$2:$H$93,A6,Inventario!$B$2:$B$93,"Catálogo PDF") -> 26 | D6: Pasan por tu mejora con IA antes de entrar al sitio.
A7: Solo texto | B7: =COUNTIF(Inventario!$H$2:$H$93,A7) -> 4 | C7: =COUNTIFS(Inventario!$H$2:$H$93,A7,Inventario!$B$2:$B$93,"Catálogo PDF") -> 4 | D7: Se aprovecha el texto, no las imágenes.
A8: Descartar | B8: =COUNTIF(Inventario!$H$2:$H$93,A8) -> 11 | C8: =COUNTIFS(Inventario!$H$2:$H$93,A8,Inventario!$B$2:$B$93,"Catálogo PDF") -> 9 | D8: Stock, fotos borrosas, material de terceros o texto genérico.
A9: Pendiente de datos | B9: =COUNTIF(Inventario!$H$2:$H$93,A9) -> 5 | C9: =COUNTIFS(Inventario!$H$2:$H$93,A9,Inventario!$B$2:$B$93,"Catálogo PDF") -> 5 | D9: Se publican solo con nombre y foto.
A10: Total de filas | B10: =SUM(B5:B9) -> 92 | C10: =SUM(C5:C9) -> 67
A12: Calidad de imagen | B12: Total | C12: Del catálogo PDF
A13: Alta | B13: =COUNTIF(Inventario!$G$2:$G$93,A13) -> 24 | C13: =COUNTIFS(Inventario!$G$2:$G$93,A13,Inventario!$B$2:$B$93,"Catálogo PDF") -> 16
A14: Media | B14: =COUNTIF(Inventario!$G$2:$G$93,A14) -> 46 | C14: =COUNTIFS(Inventario!$G$2:$G$93,A14,Inventario!$B$2:$B$93,"Catálogo PDF") -> 32
A15: Baja | B15: =COUNTIF(Inventario!$G$2:$G$93,A15) -> 18 | C15: =COUNTIFS(Inventario!$G$2:$G$93,A15,Inventario!$B$2:$B$93,"Catálogo PDF") -> 15
A16: n/a | B16: =COUNTIF(Inventario!$G$2:$G$93,A16) -> 4 | C16: =COUNTIFS(Inventario!$G$2:$G$93,A16,Inventario!$B$2:$B$93,"Catálogo PDF") -> 4
A18: Páginas del sitio con contenido completo | B18: =COUNTIF('Páginas del sitio'!$H$2:$H$30,"Completo") -> 14
A19: Páginas del sitio con contenido parcial | B19: =COUNTIF('Páginas del sitio'!$H$2:$H$30,"Parcial") -> 15

Sheet Inventario
A1: ID | B1: Origen | C1: Pág. / Archivo | D1: Contenido | E1: Tipo | F1: Mejor foto nativa (px) | G1: Calidad | H1: Decisión | I1: Destino provisional en el sitio | J1: Nombre de archivo sugerido | K1: Acción de mejora (tuya) | L1: Notas
A2: P01 | B2: Catálogo PDF | C2: Pág. 1 | D2: Portada: Presentación de proyectos, Soluciones integrales | E2: Stock + texto | F2: 533×800 (71 ppi) | G2: Baja | H2: Descartar | I2: — | J2: — | K2: — | L2: Mano con engranajes (stock, ~22 ppi). Solo se aprovecha el lema "Soluciones integrales".
A3: P02 | B3: Catálogo PDF | C3: Pág. 2 | D3: Quiénes somos: diseño, construcción, montaje, mantenimiento y consultoría | E3: Texto + stock | F3: 600×420 (35 ppi) | G3: Baja | H3: Solo texto | I3: / y /nosotros | J3: — | K3: — | L3: Reescribir el texto. Engranajes de stock: descartar.
A4: P03 | B4: Catálogo PDF | C4: Pág. 3 | D4: Equipo de trabajo: ingenierías y personal técnico | E4: Texto | F4: — | G4: n/a | H4: Solo texto | I4: /nosotros | J4: — | K4: — | L4: Convertir en bloque de disciplinas con íconos, sin foto.
A5: P04 | B5: Catálogo PDF | C5: Pág. 4 | D5: Experiencia empresarial (página vacía) | E5: Stock | F5: 621×1080 (96 ppi) | G5: n/a | H5: Pendiente de datos | I5: /nosotros | J5: — | K5: — | L5: Faltan años de trayectoria, cantidad de proyectos y regiones atendidas.
A6: P05 | B6: Catálogo PDF | C6: Pág. 5 | D6: Separador Diseño-Construcción-Montaje | E6: Stock | F6: 800×433 (73 ppi) | G6: Baja | H6: Descartar | I6: — | J6: — | K6: — | L6: Solo sirve como nombre de categoría.
A7: P06 | B7: Catálogo PDF | C7: Pág. 6 | D7: Planta separadora de residuos sólidos, 300 t/día | E7: Render 3D | F7: 626×389 (64 ppi) | G7: Media | H7: Usar tras mejorar | I7: /industrial/planta-separadora-residuos-solidos | J7: planta-separadora-residuos-solidos-render.jpg | K7: Escalar ×2 | L7: Render de diseño; sin más datos que la capacidad.
A8: P07 | B8: Catálogo PDF | C8: Pág. 7 | D8: Sistema de enfriamiento para matadero de pollos | E8: Render / montaje | F8: 800×416 (63 ppi) | G8: Media | H8: Usar tras mejorar | I8: /industrial/sistema-enfriamiento-matadero-pollos | J8: sistema-enfriamiento-matadero-pollos-render.jpg | K8: Escalar ×2 | L8: Solo título e imagen: ficha parcial.
A9: P08 | B9: Catálogo PDF | C9: Pág. 8 | D9: Tres renders 3D de sistemas de tuberías e intercambiador | E9: Render 3D | F9: 800×416 (66 ppi) | G9: Media | H9: Usar tras mejorar | I9: / (sección Ingeniería y diseño 3D) | J9: ingenieria-diseno-3d-01.jpg … 03.jpg | K9: Escalar ×2 | L9: Lo más profesional visualmente; sin texto asociado.
A10: P09 | B10: Catálogo PDF | C10: Pág. 9 | D10: Tambores para elevador de cangilones (eje SAE1045, acero A36, pernos grado 8, antiabrasivo) | E10: Foto + render + texto | F10: 800×534 (97 ppi) | G10: Media | H10: Usar tras mejorar | I10: /industrial/elevador-de-cangilones | J10: elevador-de-cangilones-tambores.jpg | K10: Escalar ×2 | L10: Fusionar con p. 17 en una sola ficha.
A11: P10 | B11: Catálogo PDF | C11: Pág. 10 | D11: Molino de martillos (AISI 304, 200–300 kg/h) | E11: Foto + diagrama + texto | F11: 723×418 (85 ppi) | G11: Media | H11: Usar tras mejorar | I11: /industrial/molino-de-martillos | J11: molino-de-martillos-acero-inoxidable.jpg | K11: Escalar ×2 | L11: Texto completo. Corregir "DIMENSINES".
A12: P11 | B12: Catálogo PDF | C12: Pág. 11 | D12: Proyecto ejecutado: Santa Cruz, Planta Cuatro Cañadas (tira de 4 fotos) | E12: Foto (tira) | F12: 2404×1042 (123 ppi) | G12: Media | H12: Usar tras mejorar | I12: /proyectos/planta-cuatro-canadas | J12: planta-cuatro-canadas-01.jpg | K12: Recortar cada foto y escalar ×2 | L12: Una sola imagen contiene varias fotos.
... A27: P26 | B27: Catálogo PDF | C27: Pág. 26 | D27: Grupo electrógeno (diagrama de dimensiones) | E27: Diagrama | F27: 800×464 (82 ppi) | G27: Media | H27: Usar | I27: /industrial/grupo-electrogeno | J27: grupo-electrogeno-diagrama.png | K27: Opcional | L27: Sin datos técnicos escritos.
A28: P27 | B28: Catálogo PDF | C28: Pág. 27 | D28: Centro de Salud Centinela, Sucre (3 fotos de tableros y equipos) | E28: Foto | F28: 602×419 (70 ppi) | G28: Media | H28: Usar tras mejorar | I28: /proyectos/grupo-electrogeno-eba-y-centro-de-salud | J28: centro-salud-centinela-tablero.jpg | K28: Escalar ×2
A29: P28 | B29: Catálogo PDF | C29: Pág. 28 | D29: EBA, Beni (tira de fotos de tablero y motor) | E29: Foto (tira) | F29: 1862×773 (96 ppi) | G29: Alta | H29: Usar | I29: /proyectos/grupo-electrogeno-eba-y-centro-de-salud | J29: eba-beni-grupo-electrogeno.jpg | K29: Recortar fotos | L29: Buen detalle de motor y tablero.
A30: P29 | B30: Catálogo PDF | C30: Pág. 29 | D30: Separador Consultoría | E30: Stock | F30: 800×433 (73 ppi) | G30: Baja | H30: Descartar | I30: — | J30: — | K30: —
A31: P30 | B31: Catálogo PDF | C31: Pág. 30 | D31: Estudio y diseño: planta de acopio y transformación de chirimoya y durazno, Presto | E31: Diagrama + texto | F31: 795×485 (78 ppi) | G31: Media | H31: Usar tras mejorar | I31: /consultoria/estudios-y-diseno-de-plantas | J31: estudio-planta-durazno-chirimoya-presto.png | K31: Redibujar en vector | L31: Corregir "ESCENCIA".
A32: P31 | B32: Catálogo PDF | C32: Pág. 31 | D32: Estudio y diseño: planta procesadora de hortalizas, Las Carreras | E32: Diagrama + texto | F32: 800×444 (70 ppi) | G32: Media | H32: Usar tras mejorar | I32: /consultoria/estudios-y-diseno-de-plantas | J32: estudio-planta-hortalizas-las-carreras.png | K32: Redibujar en vector
A33: P32 | B33: Catálogo PDF | C33: Pág. 32 | D33: Estudio y diseño: planta de alimento balanceado, Sucre | E33: Diagrama + texto | F33: — | G33: Media | H33: Usar tras mejorar | I33: /consultoria/estudios-y-diseno-de-plantas | J33: estudio-planta-alimento-balanceado-sucre.png | K33: Redibujar en vector
A34: P33 | B34: Catálogo PDF | C34: Pág. 33 | D34: Estudio y diseño: planta de alimento balanceado, Tarija | E34: Diagrama + texto | F34: 800×492 (86 ppi) | G34: Media | H34: Usar tras mejorar | I34: /consultoria/estudios-y-diseno-de-plantas | J34: estudio-planta-alimento-balanceado-tarija.png | K34: Redibujar en vector
A35: P34 | B35: Catálogo PDF | C35: Pág. 34 | D35: Estudio y diseño: planta empaquetadora de manzana, Culpina | E35: Diagrama + texto | F35: 700×508 (93 ppi) | G35: Media | H35: Usar tras mejorar | I35: /consultoria/estudios-y-diseno-de-plantas | J35: estudio-planta-empaquetadora-manzana-culpina.png | K35: Redibujar en vector | L35: Corregir "Planta de planta".
A36: P35 | B36: Catálogo PDF | C36: Pág. 35 | D36: Separador Mantenimiento industrial | E36: Stock | F36: 800×433 (72 ppi) | G36: Baja | H36: Descartar | I36: — | J36: — | K36: —
A37: P36 | B37: Catálogo PDF | C37: Pág. 36 | D37: Embobinado y mantenimiento de motores de bombas de agua | E37: Foto + texto | F37: 681×383 (57 ppi) | G37: Media | H37: Usar | I37: /industrial/mantenimiento-motores-y-bombas | J37: mantenimiento-motores-bombas-agua.jpg | K37: Opcional | L37: Tipos: sumergibles, periféricas, centrífugas, multietapa.
A38: P37 | B38: Catálogo PDF | C38: Pág. 37 | D38: ENVIBOL, Zudañez (tira de 4 fotos de bobinados) | E38: Foto (tira) | F38: 1723×651 (96 ppi) | G38: Media | H38: Usar | I38: /industrial/mantenimiento-motores-y-bombas | J38: envibol-zudanez-embobinado.jpg | K38: Recortar fotos | L38: Buenos detalles macro. Confirmar permiso del cliente.
A39: P38 | B39: Catálogo PDF | C39: Pág. 38 | D39: Mantenimiento de campanas, ductos, cocinas y hornos industriales (lista de tareas) | E39: Foto + texto | F39: 676×507 (80 ppi) | G39: Media | H39: Usar | I39: /industrial/mantenimiento-campanas-ductos-cocinas-hornos | J39: mantenimiento-campanas-ductos-cocinas-hornos.jpg | K39: Opcional | L39: Corregir "DEL CALDEROS".
A40: P39 | B40: Catálogo PDF | C40: Pág. 39 | D40: Caja Bancaria Estatal de Salud, La Paz (tira de 3 fotos) | E40: Foto (tira) | F40: 1920×696 (96 ppi) | G40: Alta | H40: Usar | I40: /proyectos/mantenimiento-cocinas-y-hornos-industriales | J40: caja-bancaria-estatal-salud-la-paz-mantenimiento.jpg | K40: Recortar fotos | L40: Técnico con equipo de protección.
A41: P40 | B41: Catálogo PDF | C41: Pág. 40 | D41: Mantenimiento de hornos (3 fotos) | E41: Foto | F41: 428×570 (71 ppi) | G41: Baja | H41: Usar tras mejorar | I41: /proyectos/mantenimiento-cocinas-y-hornos-industriales | J41: mantenimiento-hornos-industriales.jpg | K41: Escalar ×3 | L41: Marca de terceros visible en los hornos.
A42: P41 | B42: Catálogo PDF | C42: Pág. 41 | D42: Mantenimiento de planta purificadora de agua para hemodiálisis (La Guardia) | E42: Foto (tira) + texto | F42: 1567×539 (96 ppi) | G42: Media | H42: Usar | I42: /hospitalaria/mantenimiento-planta-agua-hemodialisis | J42: mantenimiento-planta-agua-hemodialisis-la-guardia.jpg | K42: Opcional | L42: Texto pegado sin espacios; confirmar permiso para nombrar al municipio.
A43: P42 | B43: Catálogo PDF | C43: Pág. 42 | D43: Mantenimiento de ollas marmitas (15 L) | E43: Foto + texto | F43: 600×800 (66 ppi) | G43: Media | H43: Usar tras mejorar | I43: /industrial/mantenimiento-ollas-marmitas-y-carro-termico | J43: mantenimiento-ollas-marmitas.jpg | K43: Escalar ×2 | L43: Corregir "REACONIDICONAMIENTO".
A44: P43 | B44: Catálogo PDF | C44: Pág. 43 | D44: CNS Chuquisaca, Servicio de nutrición (3 fotos) | E44: Foto | F44: 800×450 (33 ppi) | G44: Baja | H44: Descartar | I44: — | J44: — | K44: Reconsiderar si se mejora | L44: Fotos de 33–39 ppi: demasiado borrosas.
A45: P44 | B45: Catálogo PDF | C45: Pág. 44 | D45: Mantenimiento de carro termo eléctrico (18 bandejas 30×40) | E45: Foto (tira) + texto | F45: 1641×600 (100 ppi) | G45: Media | H45: Usar | I45: /industrial/mantenimiento-ollas-marmitas-y-carro-termico | J45: mantenimiento-carro-termo-electrico.jpg | K45: Recortar fotos
A46: P45 | B46: Catálogo PDF | C46: Pág. 45 | D46: Horno convector: tabla de datos técnicos | E46: Tabla de tercero | F46: 312×303 (57 ppi) | G46: Baja | H46: Descartar | I46: — | J46: — | K46: — | L46: Tabla de la ficha de otro fabricante: no es contenido propio.
A47: P46 | B47: Catálogo PDF | C47: Pág. 46 | D47: Mantenimiento y reparación de balanzas camioneras y pesas patrón (80 t, certificación IBMETRO) | E47: Foto + texto | F47: 632×564 (66 ppi) | G47: Media | H47: Usar tras mejorar | I47: /industrial/mantenimiento-balanzas-camioneras-ibmetro | J47: mantenimiento-balanzas-camioneras-ibmetro.jpg | K47: Escalar ×2 | L47: Certificación IBMETRO: señal de confianza clave.
A48: P47 | B48: Catálogo PDF | C48: Pág. 47 | D48: YLB, Uyuni (tira de 3 fotos con grúa y pesas) | E48: Foto (tira) | F48: 1844×828 (96 ppi) | G48: Alta | H48: Usar | I48: /proyectos/mantenimiento-transformadores-ylb-y-lacteos | J48: ylb-uyuni-mantenimiento.jpg | K48: Recortar fotos | L48: Cliente de peso; confirmar permiso. Corregir "YACIMIENTOSDELITIO".
A49: P48 | B49: Catálogo PDF | C49: Pág. 48 | D49: Mantenimiento de transformadores eléctricos (procedimiento) | E49: Texto | F49: — | G49: n/a | H49: Solo texto | I49: /industrial/mantenimiento-transformadores-electricos | J49: — | K49: — | L49: Procedimiento técnico completo.
A50: P49 | B50: Catálogo PDF | C50: Pág. 49 | D50: Planta de lácteos Challapata, Oruro (transformador) | E50: Foto | F50: 800×360 (53 ppi) | G50: Media | H50: Usar | I50: /proyectos/mantenimiento-transformadores-ylb-y-lacteos | J50: lacteos-challapata-transformador.jpg | K50: Opcional
A51: P50 | B51: Catálogo PDF | C51: Pág. 50 | D51: Planta de lácteos San Lorenzo, Tarija (2 fotos) | E51: Foto | F51: 800×475 (75 ppi) | G51: Media | H51: Usar | I51: /proyectos/mantenimiento-transformadores-ylb-y-lacteos | J51: lacteos-san-lorenzo-transformador.jpg | K51: Opcional
A52: P51 | B52: Catálogo PDF | C52: Pág. 51 | D52: Planta de lácteos San Andrés, Beni (transformador) | E52: Foto | F52: 256×350 (36 ppi) | G52: Media | H52: Usar | I52: /proyectos/mantenimiento-transformadores-ylb-y-lacteos | J52: lacteos-san-andres-transformador.jpg | K52: Opcional
A53: P52 | B53: Catálogo PDF | C53: Pág. 52 | D53: Sopachuy: línea de embutidos (3 fotos verticales) | E53: Foto | F53: 1440×649 (117 ppi) | G53: Alta | H53: Usar | I53: /proyectos/sopachuy-linea-embutidos-y-matadero | J53: sopachuy-linea-embutidos-01.jpg | K53: Opcional ×2 | L53: Mejor set fotográfico del catálogo.
A54: P53 | B54: Catálogo PDF | C54: Pág. 53 | D54: Sopachuy: sistema de GLP y carro de colgado de embutidos | E54: Foto + texto | F54: 900×1600 (99 ppi) | G54: Alta | H54: Usar | I54: /proyectos/sopachuy-linea-embutidos-y-matadero | J54: sopachuy-gas-glp-carro-colgado-embutidos.jpg | K54: Opcional
...

Sheet Páginas del sitio
A1: # | B1: Ruta provisional | C1: Tipo | D1: Área | E1: Título H1 propuesto | F1: Frase objetivo SEO (hipótesis a validar) | G1: Fuentes en el catálogo / video | H1: Estado del contenido | I1: Qué falta
A2: 1 | B2: /proyectos/sopachuy-linea-embutidos-y-matadero | C2: Proyecto | D2: Industrial | E2: Línea de embutidos y equipos de matadero en Sopachuy | F2: equipos para matadero y línea de embutidos Bolivia | G2: P52–P62 + clip y fotogramas de cámara de frío + fotogramas del cajón | H2: Parcial | I2: Datos técnicos de P59–P62 (no disponibles): se publica con nombre y foto.
A3: 2 | B3: /proyectos/huacareta-clasificacion-naranjas-y-vapor | C3: Proyecto | D3: Industrial | E3: Línea de clasificación de naranjas y generación de vapor en Huacareta | F3: línea de clasificación de frutas Bolivia | G3: P63–P64 + 4 clips y 5 fotogramas | H3: Parcial | I3: Capacidad de la línea y del caldero [por confirmar].
A4: 3 | B4: /proyectos/hospital-jaime-mendoza-agua-purificada | C4: Proyecto | D4: Hospitalaria | E4: Agua purificada y sistemas en el Hospital Jaime Mendoza (Sucre) | F4: planta de tratamiento de agua hospitalaria Bolivia | G4: P18, P19, P21, P24 | H4: Completo | I4: Permiso para nombrar al cliente.
A5: 4 | B5: /proyectos/aire-comprimido-y-sistemas-en-salud | C5: Proyecto | D5: Hospitalaria | E5: Aire comprimido y sistemas en hospitales y centros de salud | F5: instalación de aire comprimido hospitalario | G5: P22, P23, P25 | H5: Parcial | I5: Detalle del alcance en el Hospital Chuquisaca.
A6: 5 | B6: /proyectos/mantenimiento-transformadores-ylb-y-lacteos | C6: Proyecto | D6: Industrial | E6: Mantenimiento de transformadores en YLB (Uyuni) y plantas de lácteos | F6: mantenimiento de transformadores eléctricos Bolivia | G6: P47–P51 + texto P48 | H6: Completo | I6: Permiso para nombrar a YLB.
A7: 6 | B7: /proyectos/mantenimiento-cocinas-y-hornos-industriales | C7: Proyecto | D7: Industrial | E7: Mantenimiento de cocinas y hornos industriales (La Paz y Sucre) | F7: mantenimiento de hornos industriales | G7: P38–P40, P42–P44 | H7: Parcial | I7: Fotos de P40 y P43 de baja calidad.
A8: 7 | B8: /proyectos/grupo-electrogeno-eba-y-centro-de-salud | C8: Proyecto | D8: Industrial | E8: Grupos electrógenos en EBA (Beni) y Centro de Salud Centinela | F8: instalación de grupo electrógeno Bolivia | G8: P26–P28 | H8: Parcial | I8: Potencia y modelo de los equipos.
A9: 8 | B9: /proyectos/planta-cuatro-canadas | C9: Proyecto | D9: Industrial | E9: Planta Cuatro Cañadas (Santa Cruz) | F9: — | G9: P11, P12, P16 | H9: Parcial | I9: Solo fotos; sin datos del proyecto.
A10: 9 | B10: /industrial/ensacadora-saco-valvulado | C10: Solución | D10: Industrial | E10: Ensacadora de saco valvulado | F10: ensacadora de saco valvulado | G10: P15 (+ posible P16) | H10: Completo | I10: Foto principal de mejor calidad.
A11: 10 | B11: /industrial/molino-de-martillos | C11: Solución | D11: Industrial | E11: Molino de martillos en acero inoxidable | F11: molino de martillos acero inoxidable | G11: P10 | H11: Completo
A12: 11 | B12: /industrial/humidificador-de-granos | C12: Solución | D12: Industrial | E12: Humidificador de granos de 4 t/h | F12: humidificador de granos | G12: P13 | H12: Completo
A13: 12 | B13: /industrial/tornillo-helicoidal | C13: Solución | D13: Industrial | E13: Tornillo helicoidal transportador | F13: tornillo helicoidal transportador | G13: P14 | H13: Completo
A14: 13 | B14: /industrial/elevador-de-cangilones | C14: Solución | D14: Industrial | E14: Elevador de cangilones: tambores y bandejas | F14: elevador de cangilones | G14: P9, P17 | H14: Completo
A15: 14 | B15: /industrial/planta-separadora-residuos-solidos | C15: Solución | D15: Industrial | E15: Planta separadora de residuos sólidos de 300 t/día | F15: planta separadora de residuos sólidos | G15: P6 | H15: Parcial | I15: Descripción del proceso.
A16: 15 | B16: /industrial/sistema-enfriamiento-matadero-pollos | C16: Solución | D16: Industrial | E16: Sistema de enfriamiento para matadero de pollos | F16: enfriamiento para matadero de pollos | G16: P7, P8 | H16: Parcial | I16: Descripción técnica.
A17: 16 | B17: /industrial/grupo-electrogeno | C17: Solución | D17: Industrial | E17: Diseño y montaje de grupo electrógeno | F17: grupo electrógeno instalación | G17: P26 | H17: Parcial | I17: Datos técnicos.
A18: 17 | B18: /industrial/mantenimiento-transformadores-electricos | C18: Solución | D18: Industrial | E18: Mantenimiento de transformadores eléctricos | F18: mantenimiento de transformadores eléctricos | G18: P48 | H18: Completo
A19: 18 | B19: /industrial/mantenimiento-balanzas-camioneras-ibmetro | C19: Solución | D19: Industrial | E19: Mantenimiento y reparación de balanzas camioneras con certificación IBMETRO | F19: mantenimiento de balanzas camioneras IBMETRO | G19: P46 | H19: Parcial | I19: Alcance del servicio.
A20: 19 | B20: /industrial/mantenimiento-motores-y-bombas | C20: Solución | D20: Industrial | E20: Embobinado y mantenimiento de motores de bombas de agua | F20: embobinado de motores eléctricos | G20: P36, P37 | H20: Parcial
A21: 20 | B21: /industrial/mantenimiento-campanas-ductos-cocinas-hornos | C21: Solución | D21: Industrial | E21: Mantenimiento de campanas, ductos, cocinas y hornos industriales | F21: mantenimiento de campanas y ductos industriales | G21: P38 | H21: Completo
A22: 21 | B22: /industrial/mantenimiento-ollas-marmitas-y-carro-termico | C22: Solución | D22: Industrial | E22: Mantenimiento de ollas marmitas y carros termo eléctricos | F22: mantenimiento de ollas marmitas | G22: P42, P44 | H22: Completo
A23: 22 | B23: /hospitalaria/planta-tratamiento-agua-purificada | C23: Solución | D23: Hospitalaria | E23: Planta de tratamiento de agua purificada industrial y hospitalaria | F23: planta de agua purificada hospital | G23: P18, P21 | H23: Completo
A24: 23 | B24: /hospitalaria/mantenimiento-planta-agua-hemodialisis | C24: Solución | D24: Hospitalaria | E24: Mantenimiento de plantas de agua para hemodiálisis | F24: mantenimiento planta de agua hemodiálisis | G24: P41 | H24: Completo | I24: Permiso para nombrar al municipio.
A25: 24 | B25: /hospitalaria/aire-comprimido | C25: Solución | D25: Hospitalaria | E25: Generación y montaje de sistemas de aire comprimido | F25: sistema de aire comprimido hospitalario | G25: P23 | H25: Completo
A26: 25 | B26: /hospitalaria/sistema-control-monitoreo-remoto | C26: Solución | D26: Hospitalaria | E26: Sistema de control y monitoreo remoto por llamadores | F26: sistema de llamado de emergencia hospital | G26: P20 | H26: Parcial | I26: Sin fotos propias.
A27: 26 | B27: /consultoria/estudios-y-diseno-de-plantas | C27: Servicio | D27: Consultoría | E27: Estudios y diseño técnico de plantas industriales | F27: diseño de plantas procesadoras de alimentos | G27: P30–P34 | H27: Completo | I27: Diagramas a redibujar.
A28: 27 | B28: / | C28: Página | D28: General | E28: Inicio | F28: fabricación de maquinaria industrial en Sucre | G28: P2, P6–P8, P64, logo | H28: Parcial | I28: Cifras de trayectoria (P4 vacía).
A29: 28 | B29: /nosotros | C29: Página | D29: General | E29: Nosotros | F29: empresa de ingeniería industrial en Sucre | G29: P2, P3, P66 | H29: Parcial | I29: Años de experiencia; permiso para logos de marcas.
A30: 29 | B30: /contacto | C30: Página | D30: General | E30: Contacto | F30: — | G30: Sitio actual: calle René Moreno Nº 162, Sucre; tel. (+591) 72877116 | H30: Parcial | I30: WhatsApp, correo, horarios.
B32: Rutas y títulos provisionales: se confirman en la fase de estructura del proyecto. Las frases objetivo son hipótesis basadas en el vocabulario del catálogo; falta validarlas con Search Console y el Planificador de Palabras Clave.

Sheet Textos por corregir
A1: Pág. | B1: Texto en el catálogo | C1: Corrección sugerida | D1: Nota
A2: 2 | B2: m´áquinas | C2: máquinas
A3: 2 | B3: memoria de calculó | C3: memoria de cálculo
A4: 10 | B4: DIMENSINES TÉCNICAS | C4: Dimensiones técnicas
A5: 13 | B5: DISEÑO YCONTRUCCIÓN DE EQUIPO HUMIDIFICADOR DE GRANOS | C5: Diseño y construcción de equipo humidificador de granos
A6: 14 | B6: DISEÑO Y CONTRUCCIÓN DE TORNILLO HELICOIDAL | C6: Diseño y construcción de tornillo helicoidal
A7: 14 | B7: 45GRADOS DEINCLINACIÓN | C7: 45° de inclinación
A8: 20 | B8: ELÉCTRÓNICOS | C8: electrónicos
A9: 30 | B9: ESCENCIA DURAZNO Y CHIRIMOYA | C9: Esencia de durazno y chirimoya
A10: 34 | B10: Gráfico: Planta de planta empaquetadora de manzana | C10: Gráfico: planta empaquetadora de manzana
A11: 36 | B11: MULTIETÁPICAS | C11: multietapa | D11: Confirmar con el equipo técnico.
A12: 38 | B12: DESINFECCIÓN DEL CALDEROS | C12: Desinfección de los calderos
A13: 41 | B13: PARAHEMODIÁLISISQUE ESUTILIZADAENELCENTRODESALUDINTEGRALEL CARMEN KM10DELMUNICIPIOLAGUARDIA | C13: para hemodiálisis, que se utiliza en el Centro de Salud Integral El Carmen, km 10, municipio de La Guardia | D13: Texto pegado sin espacios.
A14: 42 | B14: REACONIDICONAMIENTO INTEGRAL DE LA ESTRUCTURA METALICA | C14: Reacondicionamiento integral de la estructura metálica
A15: 47 | B15: YACIMIENTOSDELITIO BOLIVIANOS YLB | C15: Yacimientos de Litio Bolivianos (YLB)
A16: 55 | B16: Maquina Envasadora al vacío | C16: Máquina envasadora al vacío
A17: 59 | B17: DESCRIPCION / DATOS TECNICOS | C17: Descripción / Datos técnicos | D17: Sin contenido.
A18: 60 | B18: Cierra divisoria | C18: ¿Cierre divisorio? | D18: Confirmar con el cliente.
A19: 61 | B19: Tuna de escaldado | C19: ¿Tina de escaldado? | D19: Confirmar con el cliente.

Sheet Pendientes
A1: # | B1: Tarea | C1: Responsable | D1: Estado | E1: Detalle
A2: 1 | B2: Mejorar con IA las fotos marcadas "Usar tras mejorar" | C2: Tú | D2: Pendiente | E2: Escalar sin regenerar: la maquinaria debe verse igual que en la realidad. Mínimo 1600 px en fotos principales y 1200 px en galería.
A3: 2 | B3: Mejorar con IA los 5 clips recortados | C3: Tú | D3: Pendiente | E3: Escalar ×2 sin regenerar; entregar en MP4 sin audio.
A4: 3 | B4: Confirmar permiso para nombrar clientes públicamente | C4: Tú | D4: Pendiente | E4: Hospital Jaime Mendoza, CNS, Hospital Chuquisaca, YLB, EBA, ENVIBOL, Caja Bancaria Estatal de Salud, Gobierno Municipal de La Guardia.
A5: 4 | B5: Conseguir años de trayectoria y cantidad de proyectos (P4 vacía) | C5: Tú | D5: Pendiente | E5: Sin esos datos no se puede armar la franja de cifras de la home.
A6: 5 | B6: Datos de contacto: WhatsApp, correo y horarios | C6: Tú | D6: Pendiente | E6: Teléfono y dirección ya están en el sitio actual.
A7: 6 | B7: Conseguir los logos de las marcas (P66) en SVG | C7: Tú | D7: Pendiente | E7: Titular sugerido: "Marcas con las que trabajamos". No sugerir distribución autorizada si no lo es.
A8: 7 | B8: Confirmar si la ensacadora de la P16 es la misma de la P15 | C8: Tú | D8: Pendiente | E8: La P15 tiene una foto de 333×453; la P16 podría ofrecer una mejor.
A9: 8 | B9: Recortar las fotos individuales de las tiras (P11, 12, 25, 28, 37, 39, 41, 44, 47) | C9: Claude | D9: Pendiente | E9: Se hace en la fase de armado del proyecto.
A10: 9 | B10: Redactar textos largos con datos reales y marcas [por confirmar] | C10: Claude | D10: Pendiente | E10: Mínimo ~300 palabras por página, sin inventar especificaciones.
A11: 10 | B11: Definir la estructura del proyecto y las rutas definitivas | C11: Ambos | D11: Siguiente | E11: Siguiente paso, ya con este inventario.
